<?xml version="1.0"?>
<!-- URDF model of Kinova Gen 3 robot arm with Robotiq Hand-E gripper for PyBullet -->
<robot name="KinovaG3_7DOF_HandEgrip" xmlns:xacro="http://ros.org/wiki/xacro">
  <link name="base_link">
    <inertial>
      <origin xyz="-0.000648 -0.000166 0.084487" rpy="0 0 0" />
      <mass value="1.697" />
      <inertia ixx="0.004622" ixy="9E-06" ixz="6E-05" iyy="0.004495" iyz="9E-06" izz="0.002079" />
    </inertial>
    <visual>
      <origin xyz="0 0 0" rpy="0 0 0"/>
      <geometry>
        <mesh filename="file://meshes/arm/base_adj.dae" />
      </geometry>
      <material name="white">
        <color rgba="1.0 1.0 1.0 1" />
      </material>
    </visual>
    <collision>
      <origin xyz="0 0 0.0854" rpy="-3.1415894 0 0"/>
      <geometry>
        <cylinder radius="0.046" length="0.1708"/>
      </geometry>
    </collision>
  </link>
  <joint name="Actuator1" type="continuous">
    <parent link="base_link"/>
    <child link="shoulder"/>
    <axis xyz="1.2246469e-16 0 1"/>
    <limit effort="54" velocity="1.361"/>
    <origin xyz="0 0 0.15643" rpy="3.1415927 1.2246469e-16 3.1415927"/>
  </joint>
  <link name="shoulder">
    <inertial>
      <origin xyz="-2.3E-05 -0.010364 -0.07336" rpy="0 0 0" />
      <mass value="1.3773" />
      <inertia ixx="0.00457" ixy="1E-06" ixz="2E-06" iyy="0.004831" iyz="0.000448" izz="0.001409" />
    </inertial>
    <visual>
      <origin xyz="0 0 0" rpy="0 0 0"/>
      <geometry>
        <mesh filename="file://meshes/arm/shoulder_adj.dae" />
      </geometry>
    </visual>
    <collision>
      <origin xyz="0 0 -0.038" rpy="-3.3939336e-06 0 0"/>
      <geometry>
        <cylinder radius="0.046" length="0.0435"/>
      </geometry>
    </collision>
    <collision>
      <origin xyz="0 -0.026 -0.0925" rpy="0 0 0"/>
      <geometry>
        <box size="0.092 0.04 0.075"/>
      </geometry>
    </collision>
    <collision>
      <origin xyz="0 -0.0152 -0.12856" rpy="1.5707963 0 0"/>
      <geometry>
        <cylinder radius="0.047" length="0.07"/>
      </geometry>
    </collision>
  </link>
  <joint name="Actuator2" type="revolute">
    <parent link="shoulder"/>
    <child link="half_arm_1"/>
    <axis xyz="9.713438e-07 3.390567e-07 1"/>
    <limit effort="54" lower="-2.41" upper="2.41" velocity="1.361"/>
    <origin xyz="0 0.005375 -0.12838" rpy="1.5707964 0.29999915 -1.0167554e-06"/>
  </joint>
  <link name="half_arm_1">
    <inertial>
      <origin xyz="-4.4E-05 -0.09958 -0.013278" rpy="0 0 0" />
      <mass value="1.1636" />
      <inertia ixx="0.011088" ixy="5E-06" ixz="0" iyy="0.001072" iyz="-0.000691" izz="0.011255" />
    </inertial>
    <visual>
      <origin xyz="0 0 0" rpy="0 0 0"/>
      <geometry>
        <mesh filename="file://meshes/arm/halfArm1_adj.dae" />
      </geometry>
    </visual>
    <collision>
      <origin xyz="0 0 -0.0364" rpy="-3.1415894 0 0"/>
      <geometry>
        <cylinder radius="0.046" length="0.038"/>
      </geometry>
    </collision>
    <collision>
      <origin xyz="0 -0.07 -0.036" rpy="-0.055 0 0"/>
      <geometry>
        <box size="0.092 0.136 0.03"/>
      </geometry>
    </collision>
    <collision>
      <origin xyz="0 -0.1792 -0.0064" rpy="1.5707963 0 0"/>
      <geometry>
        <cylinder radius="0.046" length="0.09"/>
      </geometry>
    </collision>
    <collision>
      <origin xyz="0 -0.1105 -0.0155" rpy="-0.52 0 0"/>
      <geometry>
        <box size="0.092 0.085 0.03"/>
      </geometry>
    </collision>
  </link>
  <joint name="Actuator3" type="continuous">
    <parent link="half_arm_1"/>
    <child link="half_arm_2"/>
    <axis xyz="0 -3.3671047e-06 1"/>
    <limit effort="54" velocity="1.361"/>
    <origin xyz="0 -0.21038 -0.006375" rpy="-1.5707997 0 0"/>
  </joint>
  <link name="half_arm_2">
    <inertial>
      <origin xyz="-4.4E-05 -0.006641 -0.117892" rpy="0 0 0" />
      <mass value="1.1636" />
      <inertia ixx="0.010932" ixy="0" ixz="-7E-06" iyy="0.011127" iyz="0.000606" izz="0.001043" />
    </inertial>
    <visual>
      <origin xyz="0 0 0" rpy="0 0 0"/>
      <geometry>
        <mesh filename="file://meshes/arm/halfArm2_adj.dae" />
      </geometry>
    </visual>
    <collision>
      <origin xyz="0 0 -0.0439" rpy="-3.1415894 0 0"/>
      <geometry>
        <cylinder radius="0.046" length="0.055"/>
      </geometry>
    </collision>
    <collision>
      <origin xyz="0 -0.0323 -0.1394" rpy="0 0 0"/>
      <geometry>
        <box size="0.092 0.035 0.142"/>
      </geometry>
    </collision>
    <collision>
      <origin xyz="0 -0.0148 -0.2104" rpy="1.5707963 0 0"/>
      <geometry>
        <cylinder radius="0.046" length="0.07"/>
      </geometry>
    </collision>
    <collision>
      <origin xyz="0 -0.012 -0.1004" rpy="-0.48 0 0"/>
      <geometry>
        <box size="0.092 0.038 0.088"/>
      </geometry>
    </collision>
  </link>
  <joint name="Actuator4" type="revolute">
    <parent link="half_arm_2"/>
    <child link="forearm"/>
    <axis xyz="-3.7824321e-07 3.79854e-06 1"/>
    <limit effort="54" lower="-2.66" upper="2.66" velocity="1.361"/>
    <origin xyz="0 0.006375 -0.21038" rpy="-1.5708054 1.5415918 3.1415796"/>
  </joint>
  <link name="forearm">
    <inertial>
      <origin xyz="-1.8E-05 -0.075478 -0.015006" rpy="0 0 0" />
      <mass value="0.9302" />
      <inertia ixx="0.008147" ixy="-1E-06" ixz="0" iyy="0.000631" iyz="-0.0005" izz="0.008316" />
    </inertial>
    <visual>
      <origin xyz="0 0 0" rpy="0 0 0"/>
      <geometry>
        <mesh filename="file://meshes/arm/forearm_adj.dae" />
      </geometry>
    </visual>
    <collision>
      <origin xyz="0 0 -0.036" rpy="-3.1415894 0 0"/>
      <geometry>
        <cylinder radius="0.046" length="0.04"/>
      </geometry>
    </collision>
    <collision>
      <origin xyz="0 -0.035 -0.0376" rpy="0 0 0"/>
      <geometry>
        <box size="0.07 0.07 0.032"/>
      </geometry>
    </collision>
    <collision>
      <origin xyz="0 -0.115 -0.0315" rpy="-0.1308997 0 0"/>
      <geometry>
        <box size="0.07 0.095 0.032"/>
      </geometry>
    </collision>
    <collision>
      <origin xyz="0 -0.125 -0.0133" rpy="-0.5235997 0 0"/>
      <geometry>
        <box size="0.07 0.09 0.032"/>
      </geometry>
    </collision>
    <collision>
      <origin xyz="0 -0.1884 -0.0064" rpy="1.5707963 0 0"/>
      <geometry>
        <cylinder radius="0.035" length="0.065"/>
      </geometry>
    </collision>
  </link>
  <joint name="Actuator5" type="continuous">
    <parent link="forearm"/>
    <child link="wrist1"/>
    <axis xyz="0 -3.3671047e-06 1"/>
    <limit effort="34" velocity="2.618"/>
    <origin xyz="0 -0.20843 -0.006375" rpy="-1.5707997 0 0"/>
  </joint>
  <link name="wrist1">
    <inertial>
      <origin xyz="1E-06 -0.009432 -0.063883" rpy="0 0 0" />
      <mass value="0.6781" />
      <inertia ixx="0.001596" ixy="0" ixz="0" iyy="0.001607" iyz="0.000256" izz="0.000399" />
    </inertial>
    <visual>
      <origin xyz="0 0 0" rpy="0 0 0"/>
      <geometry>
        <mesh filename="file://meshes/arm/wrist1_adj.dae" />
      </geometry>
    </visual>
    <collision>
      <origin xyz="0 0 -0.0319" rpy="-3.1415894 0 0"/>
      <geometry>
        <cylinder radius="0.035" length="0.035"/>
      </geometry>
    </collision>
    <collision>
      <origin xyz="0 -0.02875 -0.06655" rpy="-0.22 0 0"/>
      <geometry>
        <box size="0.07 0.027 0.065"/>
      </geometry>
    </collision>
    <collision>
      <origin xyz="0 -0.02085 -0.1059" rpy="1.5707963 0 0"/>
      <geometry>
        <cylinder radius="0.035" length="0.067"/>
      </geometry>
    </collision>
  </link>
  <joint name="Actuator6" type="revolute">
    <parent link="wrist1"/>
    <child link="wrist2"/>
    <axis xyz="5.792202e-08 2.207132e-06 1"/>
    <limit effort="34" lower="-2.23" upper="2.23" velocity="2.618"/>
    <origin xyz="0 0.00017505 -0.10593" rpy="1.5707984 0.99999905 -1.0720282e-07"/>
  </joint>
  <link name="wrist2">
    <inertial>
      <origin xyz="1E-06 -0.045483 -0.00965" rpy="0 0 0" />
      <mass value="0.6781" />
      <inertia ixx="0.001641" ixy="0" ixz="0" iyy="0.00041" iyz="-0.000278" izz="0.001641" />
    </inertial>
    <visual>
      <origin xyz="0 0 0" rpy="0 0 0"/>
      <geometry>
        <mesh filename="file://meshes/arm/wrist2_adj.dae" />
      </geometry>
    </visual>
    <collision>
      <origin xyz="0 0 -0.0344" rpy="-3.1415894 0 0"/>
      <geometry>
        <cylinder radius="0.035" length="0.04"/>
      </geometry>
    </collision>
    <collision>
      <origin xyz="0 -0.0404 -0.0288" rpy="-0.22 0 0"/>
      <geometry>
        <box size="0.07 0.065 0.027"/>
      </geometry>
    </collision>
    <collision>
      <origin xyz="0 -0.08844 -0.0002" rpy="1.5707963 0 0"/>
      <geometry>
        <cylinder radius="0.035" length="0.06"/>
      </geometry>
    </collision>
  </link>
  <joint name="Actuator7" type="continuous">
    <parent link="wrist2"/>
    <child link="bracelet_w_camera"/>
    <axis xyz="-5.182391e-07 -3.9823344e-06 1"/>
    <limit effort="34" velocity="2.618"/>
    <origin xyz="0 -0.10593 -0.00017505" rpy="1.7001996 1.5707923 -3.0121853"/>
  </joint>
  <link name="bracelet_w_camera">
    <inertial>
      <origin xyz="-0.000281 -0.011402 -0.029798" rpy="0 0 0" />
      <mass value="0.5006" />
      <inertia ixx="0.000587" ixy="3E-06" ixz="3E-06" iyy="0.000369" iyz="0.000118" izz="0.000609" />
    </inertial>
    <visual>
      <origin xyz="0 0 0" rpy="0 0 0"/>
      <geometry>
        <mesh filename="file://meshes/arm/bracelet_vision.dae" />
      </geometry>
    </visual>
    <collision>
      <origin xyz="0 0 -0.039425" rpy="-3.1415894 0 0"/>
      <geometry>
        <cylinder radius="0.0375" length="0.05"/>
      </geometry>
    </collision>
    <collision>
      <origin xyz="0 -0.036 -0.0493" rpy="0 0 0"/>
      <geometry>
        <box size="0.05 0.02 0.022"/>
      </geometry>
    </collision>
    <collision>
      <origin xyz="0 -0.05967 -0.04925" rpy="0 0 0"/>
      <geometry>
        <box size="0.091 0.03 0.022"/>
      </geometry>
    </collision>
  </link>
  <link name="Robotiq_HandE_gripper">
    <inertial>
      <mass value="0.89" />
      <inertia ixx="0.00534" ixy="1E-06" ixz="1E-06" iyy="0.00545" iyz="1E-06" izz="0.000636" />
    </inertial>
    <visual>
      <origin xyz="0 0 0.0859" rpy="1.5707991 0 1.5707991"/>
      <geometry>
        <mesh filename="file://meshes/gripper/base_bottom.dae" />
      </geometry>
      <material name="black">
        <color rgba="0.27 0.27 0.27 1" />
      </material>
    </visual>
    <visual>
      <origin xyz="0 0 0.0859" rpy="1.5707991 0 1.5707991"/>
      <geometry>
        <mesh filename="file://meshes/gripper/base_top.dae" />
      </geometry>
    </visual>
    <collision>
      <origin xyz="0 0 0.0191" rpy="-3.1415899 -2.827666e-06 1.5707991"/>
      <geometry>
        <cylinder radius="0.0375" length="0.032"/>
      </geometry>
    </collision>
    <collision>
      <origin xyz="0 0 0.0491" rpy="-3.1415899 -2.827666e-06 1.5707991"/>
      <geometry>
        <cylinder radius="0.026" length="0.036"/>
      </geometry>
    </collision>
    <collision>
      <origin xyz="0 0 0.0811" rpy="1.5707991 -2.8276386e-06 1.5707991"/>
      <geometry>
        <box size="0.062 0.036 0.075"/>
      </geometry>
    </collision>
  </link>
  <joint name="gripper_joint" type="fixed">
    <parent link="bracelet_w_camera"/>
    <child link="Robotiq_HandE_gripper"/>
    <origin xyz="0 0 -0.061525" rpy="3.1415858 0 0"/>
  </joint>
  <joint name="grip_actuator_L" type="prismatic">
    <parent link="Robotiq_HandE_gripper"/>
    <child link="left_finger_assembly"/>
    <axis xyz="2.8276306e-06 2.8276386e-06 1"/>
    <origin xyz="0 0 0.0859" rpy="1.5707991 2.8276386e-06 -1.5707991"/>
    <limit effort="185" lower="-0.0003" upper="0.030745" velocity="0.15"/>
  </joint>
  <link name="left_finger_assembly">
    <contact>
      <friction_anchor/>
      <stiffness value="30000.0"/>
      <damping value="1000.0"/>
      <spinning_friction value="0.03"/>
      <lateral_friction value="1.0"/>
    </contact>
    <inertial>
      <mass value="0.04" />
      <inertia ixx="0.1" ixy="1E-06" ixz="1E-06" iyy="0.1" iyz="1E-06" izz="0.1" />
    </inertial>
    <visual>
      <origin xyz="0 0 0" rpy="0 3.1415858 0"/>
      <geometry>
        <mesh filename="file://meshes/gripper/extended_finger.dae" />
      </geometry>
      <material name="grey">
        <color rgba="0.57 0.57 0.57 1" />
      </material>
    </visual>
    <collision>
      <origin xyz="0.00558 0.0146 -0.0492765" rpy="0 0 0"/>
      <geometry>
        <box size="0.02734 0.002 0.037075"/>
      </geometry>
    </collision>
    <collision>
      <origin xyz="0.00558 0.0169 -0.061664" rpy="0 0 0"/>
      <geometry>
        <box size="0.02734 0.0066 0.0123"/>
      </geometry>
    </collision>
    <collision>
      <origin xyz="0.01425 0.0169 -0.041814" rpy="0 0 0"/>
      <geometry>
        <box size="0.01 0.0066 0.052"/>
      </geometry>
    </collision>
    <collision>
      <origin xyz="0 0.027267 -0.059714" rpy="0 0 0"/>
      <geometry>
        <box size="0.016 0.014134 0.0162"/>
      </geometry>
    </collision>
    <collision>
      <origin xyz="0 0.0392 -0.052557" rpy="0 0 0"/>
      <geometry>
        <box size="0.022 0.038 0.0078"/>
      </geometry>
    </collision>
  </link>
  <joint name="grip_actuator_R" type="prismatic">
    <parent link="Robotiq_HandE_gripper"/>
    <child link="right_finger_assembly"/>
    <axis xyz="-2.8276306e-06 2.8276386e-06 1"/>
    <origin xyz="0 0 0.0859" rpy="1.5707991 -2.8276386e-06 1.5707991"/>
    <limit effort="185" lower="-0.0003" upper="0.030745" velocity="0.15"/>
  </joint>
  <link name="right_finger_assembly">
    <contact>
      <friction_anchor/>
      <stiffness value="30000.0"/>
      <damping value="1000.0"/>
      <spinning_friction value="0.03"/>
      <lateral_friction value="1.0"/>
    </contact>
    <inertial>
      <mass value="0.04" />
      <inertia ixx="0.1" ixy="1E-06" ixz="1E-06" iyy="0.1" iyz="1E-06" izz="0.1" />
    </inertial>
    <visual>
      <origin xyz="0 0 0" rpy="0 3.1415858 0"/>
      <geometry>
        <mesh filename="file://meshes/gripper/extended_finger.dae" />
      </geometry>
      <material name="grey" />
    </visual>
    <collision>
      <origin xyz="0.00558 0.0146 -0.0492765" rpy="0 0 0"/>
      <geometry>
        <box size="0.02734 0.002 0.037075"/>
      </geometry>
    </collision>
    <collision>
      <origin xyz="0.00558 0.0169 -0.061664" rpy="0 0 0"/>
      <geometry>
        <box size="0.02734 0.0066 0.0123"/>
      </geometry>
    </collision>
    <collision>
      <origin xyz="0.01425 0.0169 -0.041814" rpy="0 0 0"/>
      <geometry>
        <box size="0.01 0.0066 0.052"/>
      </geometry>
    </collision>
    <collision>
      <origin xyz="0 0.027267 -0.059714" rpy="0 0 0"/>
      <geometry>
        <box size="0.016 0.014134 0.0162"/>
      </geometry>
    </collision>
    <collision>
      <origin xyz="0 0.0392 -0.052557" rpy="0 0 0"/>
      <geometry>
        <box size="0.022 0.038 0.0078"/>
      </geometry>
    </collision>
  </link>
  <!-- virtual target link -->
  <!-- Used to calculate position of gripper's business end -->
  <link name="gripper_target">
    <inertial>
      <origin rpy="0 0 0" xyz="0 0 0"/>
       <mass value="0.0"/>
       <inertia ixx="0.1" ixy="0" ixz="0" iyy="0.1" iyz="0" izz="0.1"/>
    </inertial>
  </link>
  <joint name="target_to_gripper" type="fixed">
    <parent link="Robotiq_HandE_gripper"/>
    <child link="gripper_target"/>
    <origin rpy="0 0 0" xyz="0 0 0.125"/>
  </joint>
</robot>
